Failure # 1 (occurred at 2022-01-22_21-15-19)
Traceback (most recent call last):
  File "/usr/local/lib/python3.9/site-packages/ray/tune/trial_runner.py", line 924, in _process_trial
    results = self.trial_executor.fetch_result(trial)
  File "/usr/local/lib/python3.9/site-packages/ray/tune/ray_trial_executor.py", line 787, in fetch_result
    result = ray.get(trial_future[0], timeout=DEFAULT_GET_TIMEOUT)
  File "/usr/local/lib/python3.9/site-packages/ray/_private/client_mode_hook.py", line 105, in wrapper
    return func(*args, **kwargs)
  File "/usr/local/lib/python3.9/site-packages/ray/worker.py", line 1715, in get
    raise value
ray.exceptions.RayActorError: The actor died because of an error raised in its creation task, [36mray::IMPALA.__init__()[39m (pid=54523, ip=127.0.0.1)
  File "/usr/local/lib/python3.9/site-packages/ray/rllib/agents/trainer_template.py", line 102, in __init__
    Trainer.__init__(self, config, env, logger_creator,
  File "/usr/local/lib/python3.9/site-packages/ray/rllib/agents/trainer.py", line 661, in __init__
    super().__init__(config, logger_creator, remote_checkpoint_dir,
  File "/usr/local/lib/python3.9/site-packages/ray/tune/trainable.py", line 121, in __init__
    self.setup(copy.deepcopy(self.config))
  File "/usr/local/lib/python3.9/site-packages/ray/rllib/agents/trainer_template.py", line 113, in setup
    super().setup(config)
  File "/usr/local/lib/python3.9/site-packages/ray/rllib/agents/trainer.py", line 764, in setup
    self._init(self.config, self.env_creator)
  File "/usr/local/lib/python3.9/site-packages/ray/rllib/agents/trainer_template.py", line 136, in _init
    self.workers = self._make_workers(
  File "/usr/local/lib/python3.9/site-packages/ray/rllib/agents/trainer.py", line 1727, in _make_workers
    return WorkerSet(
  File "/usr/local/lib/python3.9/site-packages/ray/rllib/evaluation/worker_set.py", line 87, in __init__
    remote_spaces = ray.get(self.remote_workers(
ray.exceptions.RayActorError: The actor died because of an error raised in its creation task, [36mray::RolloutWorker.__init__()[39m (pid=54522, ip=127.0.0.1)
  File "/usr/local/lib/python3.9/site-packages/ray/rllib/evaluation/rollout_worker.py", line 587, in __init__
    self._build_policy_map(
  File "/usr/local/lib/python3.9/site-packages/ray/rllib/evaluation/rollout_worker.py", line 1551, in _build_policy_map
    self.policy_map.create_policy(name, orig_cls, obs_space, act_space,
  File "/usr/local/lib/python3.9/site-packages/ray/rllib/policy/policy_map.py", line 139, in create_policy
    class_(observation_space, action_space, merged_config)
  File "/usr/local/lib/python3.9/site-packages/ray/rllib/policy/eager_tf_policy.py", line 136, in __init__
    super(TracedEagerPolicy, self).__init__(*args, **kwargs)
  File "/usr/local/lib/python3.9/site-packages/ray/rllib/policy/eager_tf_policy.py", line 388, in __init__
    self.exploration = self._create_exploration()
  File "/usr/local/lib/python3.9/site-packages/ray/rllib/policy/policy.py", line 712, in _create_exploration
    exploration = from_config(
  File "/usr/local/lib/python3.9/site-packages/ray/rllib/utils/from_config.py", line 192, in from_config
    object_ = constructor(*ctor_args, **ctor_kwargs)
  File "/usr/local/lib/python3.9/site-packages/ray/rllib/utils/exploration/curiosity.py", line 109, in __init__
    raise ValueError(
ValueError: Curiosity exploration currently does not support parallelism. `num_workers` must be 0!

