Failure # 1 (occurred at 2022-01-31_15-27-41)
Traceback (most recent call last):
  File "/usr/local/lib/python3.9/site-packages/ray/tune/trial_runner.py", line 924, in _process_trial
    results = self.trial_executor.fetch_result(trial)
  File "/usr/local/lib/python3.9/site-packages/ray/tune/ray_trial_executor.py", line 787, in fetch_result
    result = ray.get(trial_future[0], timeout=DEFAULT_GET_TIMEOUT)
  File "/usr/local/lib/python3.9/site-packages/ray/_private/client_mode_hook.py", line 105, in wrapper
    return func(*args, **kwargs)
  File "/usr/local/lib/python3.9/site-packages/ray/worker.py", line 1713, in get
    raise value.as_instanceof_cause()
ray.exceptions.RayTaskError: [36mray::PPO.train()[39m (pid=14620, ip=127.0.0.1, repr=PPO)
  File "/usr/local/lib/python3.9/site-packages/ray/tune/trainable.py", line 314, in train
    result = self.step()
  File "/usr/local/lib/python3.9/site-packages/ray/rllib/agents/trainer.py", line 867, in step
    result = self.step_attempt()
  File "/usr/local/lib/python3.9/site-packages/ray/rllib/agents/trainer.py", line 920, in step_attempt
    step_results = next(self.train_exec_impl)
  File "/usr/local/lib/python3.9/site-packages/ray/util/iter.py", line 756, in __next__
    return next(self.built_iterator)
  File "/usr/local/lib/python3.9/site-packages/ray/util/iter.py", line 783, in apply_foreach
    for item in it:
  File "/usr/local/lib/python3.9/site-packages/ray/util/iter.py", line 783, in apply_foreach
    for item in it:
  File "/usr/local/lib/python3.9/site-packages/ray/util/iter.py", line 843, in apply_filter
    for item in it:
  File "/usr/local/lib/python3.9/site-packages/ray/util/iter.py", line 843, in apply_filter
    for item in it:
  File "/usr/local/lib/python3.9/site-packages/ray/util/iter.py", line 783, in apply_foreach
    for item in it:
  File "/usr/local/lib/python3.9/site-packages/ray/util/iter.py", line 783, in apply_foreach
    for item in it:
  File "/usr/local/lib/python3.9/site-packages/ray/util/iter.py", line 783, in apply_foreach
    for item in it:
  [Previous line repeated 1 more time]
  File "/usr/local/lib/python3.9/site-packages/ray/util/iter.py", line 876, in apply_flatten
    for item in it:
  File "/usr/local/lib/python3.9/site-packages/ray/util/iter.py", line 783, in apply_foreach
    for item in it:
  File "/usr/local/lib/python3.9/site-packages/ray/util/iter.py", line 783, in apply_foreach
    for item in it:
  File "/usr/local/lib/python3.9/site-packages/ray/util/iter.py", line 783, in apply_foreach
    for item in it:
  File "/usr/local/lib/python3.9/site-packages/ray/rllib/execution/rollout_ops.py", line 76, in sampler
    yield workers.local_worker().sample()
  File "/usr/local/lib/python3.9/site-packages/ray/rllib/evaluation/rollout_worker.py", line 757, in sample
    batches = [self.input_reader.next()]
  File "/usr/local/lib/python3.9/site-packages/ray/rllib/evaluation/sampler.py", line 103, in next
    batches = [self.get_data()]
  File "/usr/local/lib/python3.9/site-packages/ray/rllib/evaluation/sampler.py", line 265, in get_data
    item = next(self._env_runner)
  File "/usr/local/lib/python3.9/site-packages/ray/rllib/evaluation/sampler.py", line 682, in _env_runner
    base_env.send_actions(actions_to_send)
  File "/usr/local/lib/python3.9/site-packages/ray/rllib/env/base_env.py", line 424, in send_actions
    self.vector_env.vector_step(action_vector)
  File "/usr/local/lib/python3.9/site-packages/ray/rllib/env/vector_env.py", line 195, in vector_step
    obs, r, done, info = self.envs[i].step(actions[i])
  File "/Users/chicks/OneDrive - The Alan Turing Institute/Documents/Development/CybORG/cage-challenge-1/agents/hierachy_agents/hier_env.py", line 186, in step
    observation, reward, done, info = self.env.step(agent_action)
  File "/Users/chicks/OneDrive - The Alan Turing Institute/Documents/Development/cage-challenge-1/CybORG/CybORG/Agents/Wrappers/ChallengeWrapper.py", line 29, in step
    obs, reward, done, info = self.env.step(action=action)
  File "/Users/chicks/OneDrive - The Alan Turing Institute/Documents/Development/cage-challenge-1/CybORG/CybORG/Agents/Wrappers/OpenAIGymWrapper.py", line 27, in step
    result = self.env.step(self.agent_name, action)
  File "/Users/chicks/OneDrive - The Alan Turing Institute/Documents/Development/cage-challenge-1/CybORG/CybORG/Agents/Wrappers/EnumActionWrapper.py", line 20, in step
    return super().step(agent, action)
  File "/Users/chicks/OneDrive - The Alan Turing Institute/Documents/Development/cage-challenge-1/CybORG/CybORG/Agents/Wrappers/BaseWrapper.py", line 16, in step
    result = self.env.step(agent, action)
  File "/Users/chicks/OneDrive - The Alan Turing Institute/Documents/Development/cage-challenge-1/CybORG/CybORG/Agents/Wrappers/BlueTableWrapper.py", line 29, in step
    result = self.env.step(agent, action)
  File "/Users/chicks/OneDrive - The Alan Turing Institute/Documents/Development/cage-challenge-1/CybORG/CybORG/Agents/Wrappers/BaseWrapper.py", line 16, in step
    result = self.env.step(agent, action)
  File "/Users/chicks/OneDrive - The Alan Turing Institute/Documents/Development/cage-challenge-1/CybORG/CybORG/CybORG.py", line 104, in step
    return self.environment_controller.step(agent, action, skip_valid_action_check)
  File "/Users/chicks/OneDrive - The Alan Turing Institute/Documents/Development/cage-challenge-1/CybORG/CybORG/Shared/EnvironmentController.py", line 133, in step
    true_observation = self._filter_obs(self.get_true_state(self.INFO_DICT['True'])).data
  File "/Users/chicks/OneDrive - The Alan Turing Institute/Documents/Development/cage-challenge-1/CybORG/CybORG/Simulator/SimulationController.py", line 50, in get_true_state
    output = self.state.get_true_state(info)
  File "/Users/chicks/OneDrive - The Alan Turing Institute/Documents/Development/cage-challenge-1/CybORG/CybORG/Simulator/State.py", line 50, in get_true_state
    true_obs.add_process(hostid=hostname, **o)
  File "/Users/chicks/OneDrive - The Alan Turing Institute/Documents/Development/cage-challenge-1/CybORG/CybORG/Shared/Observation.py", line 83, in add_process
    process_name = CyEnums.ProcessName.parse_string(process_name)
  File "/Users/chicks/OneDrive - The Alan Turing Institute/Documents/Development/cage-challenge-1/CybORG/CybORG/Shared/Enums.py", line 270, in parse_string
    elif name == "bash" or name == "sh" or name == "sh.exe":
KeyboardInterrupt

During handling of the above exception, another exception occurred:

[36mray::PPO.train()[39m (pid=14620, ip=127.0.0.1, repr=PPO)
ray.exceptions.TaskCancelledError: Task: TaskID(b5a580ab80c95749e2dffd390478825faaf18a8501000000) was cancelled

