Failure # 1 (occurred at 2022-01-24_14-23-05)
Traceback (most recent call last):
  File "/usr/local/lib/python3.9/site-packages/ray/tune/trial_runner.py", line 924, in _process_trial
    results = self.trial_executor.fetch_result(trial)
  File "/usr/local/lib/python3.9/site-packages/ray/tune/ray_trial_executor.py", line 787, in fetch_result
    result = ray.get(trial_future[0], timeout=DEFAULT_GET_TIMEOUT)
  File "/usr/local/lib/python3.9/site-packages/ray/_private/client_mode_hook.py", line 105, in wrapper
    return func(*args, **kwargs)
  File "/usr/local/lib/python3.9/site-packages/ray/worker.py", line 1715, in get
    raise value
ray.exceptions.RayActorError: The actor died because of an error raised in its creation task, [36mray::DQN.__init__()[39m (pid=16444, ip=127.0.0.1)
  File "/usr/local/lib/python3.9/site-packages/ray/rllib/agents/trainer_template.py", line 102, in __init__
    Trainer.__init__(self, config, env, logger_creator,
  File "/usr/local/lib/python3.9/site-packages/ray/rllib/agents/trainer.py", line 661, in __init__
    super().__init__(config, logger_creator, remote_checkpoint_dir,
  File "/usr/local/lib/python3.9/site-packages/ray/tune/trainable.py", line 121, in __init__
    self.setup(copy.deepcopy(self.config))
  File "/usr/local/lib/python3.9/site-packages/ray/rllib/agents/trainer_template.py", line 113, in setup
    super().setup(config)
  File "/usr/local/lib/python3.9/site-packages/ray/rllib/agents/trainer.py", line 669, in setup
    self.config = self.merge_trainer_configs(
  File "/usr/local/lib/python3.9/site-packages/ray/rllib/agents/trainer.py", line 1801, in merge_trainer_configs
    return deep_update(config1, config2, _allow_unknown_configs,
  File "/usr/local/lib/python3.9/site-packages/ray/util/ml_utils/dict.py", line 51, in deep_update
    raise Exception("Unknown config parameter `{}` ".format(k))
Exception: Unknown config parameter `vf_loss_coeff`

